Workbook

Sheet Diagnostic
A1: 🎯 DIAGNOSTIC DASHBOARD — SSoT PRIORITAS PEKANAN 2026
A2: ⚙ INPUT | B2: Bulan (1–12) | C2: 6 | D2: Minggu ke- (1–4) | E2: 1 | F2: ← Ubah C2 (bulan 1–12) & E2 (minggu 1–4) untuk refresh semua target
A4: ▌ LAYER 1 — PERUSAHAAN | GMV ALL CHANNEL
A5: Layer | B5: Metrik | C5: Keterangan | D5: Target Bulanan (IDR) | E5: Target Mingguan (IDR) | F5: ✏ AKTUAL (IDR) | G5: Gap (IDR) | H5: Attainment | I5: Status | J5: Catatan
A6: L1 | B6: GMV All Channel | D6: =INDEX(Sheet1!$B$4:$B$15,$C$2) -> 3.9008113e+09 | E6: =D6/$E$2 -> 3.9008113e+09 | G6: =IF(F6="","",F6-E6) | H6: =IF(F6="","",IFERROR(F6/E6,0)) | I6: =IF(F6="","–",IF(H6>=1,"✅ On Track",IF(H6>=0.9,"⚠️ Caution","🚨 Lagging"))) -> – | J6: Dari Sheet1 (Sales Target)
A8: ▌ LAYER 2 — CHANNEL | Dekomposisi Traffic × Conversion Rate × AOV
A9: Layer | B9: Channel | C9: Metrik | D9: Target Bulanan | E9: Target Mingguan | F9: ✏ AKTUAL | G9: Gap | H9: Attainment / Delta | I9: Status | J9: ⚡ Diagnosis Lever
A10: L2 | B10: SHOPEE | C10: GMV (IDR) | D10: =INDEX(Sheet1!$D$4:$D$15,$C$2) -> 2.6135436e+09 | E10: =D10/$E$2 -> 2.6135436e+09 | G10: =IF(F10="","",F10-E10) | H10: =IF(F10="","",IFERROR(F10/E10,0)) | I10: =IF(F10="","–",IF(H10>=1,"✅",IF(H10>=0.9,"⚠️","🚨"))) -> – | J10: =IF(OR(F11="",F12="",F13=""),"isi aktual dulu",IF(AND(H11<=H12,H11<=H13),"⬇ Traffic drag",IF(AND(H12<=H11,H12<=H13),"⬇ CVR drag","⬇ AOV drag"))) -> isi aktual dulu
C11: Traffic (Visitor) | D11: =INDEX(Sheet1!$N$24:$N$35,$C$2) -> 399000 | E11: =D11/$E$2 -> 399000 | G11: =IF(F11="","",F11-E11) | H11: =IF(F11="","",IFERROR(F11/E11,0)) | I11: =IF(F11="","–",IF(H11>=1,"✅",IF(H11>=0.9,"⚠️","🚨"))) -> –
C12: CVR (%) | D12: 0.072 | E12: =D12 -> 0.072 | G12: =IF(F12="","",F12-E12) | H12: =IF(F12="","",IFERROR(F12/E12,0)) | I12: =IF(F12="","–",IF(H12>=1,"✅",IF(H12>=0.9,"⚠️","🚨"))) -> –
C13: AOV (IDR/order) | D13: 105000 | E13: =D13 -> 105000 | G13: =IF(F13="","",F13-E13) | H13: =IF(F13="","",IFERROR(F13/E13,0)) | I13: =IF(F13="","–",IF(H13>=1,"✅",IF(H13>=0.9,"⚠️","🚨"))) -> –
A15: L2 | B15: TIKTOKSHOP | C15: GMV (IDR) | D15: =INDEX(Sheet1!$F$4:$F$15,$C$2) -> 1.1507393e+09 | E15: =D15/$E$2 -> 1.1507393e+09 | G15: =IF(F15="","",F15-E15) | H15: =IF(F15="","",IFERROR(F15/E15,0)) | I15: =IF(F15="","–",IF(H15>=1,"✅",IF(H15>=0.9,"⚠️","🚨"))) -> – | J15: =IF(OR(F16="",F17="",F18=""),"isi aktual dulu",IF(AND(H16<=H17,H16<=H18),"⬇ Traffic drag",IF(AND(H17<=H16,H17<=H18),"⬇ CVR drag","⬇ AOV drag"))) -> isi aktual dulu
C16: Traffic (Visitor) | D16: =INDEX(Sheet1!$G$43:$G$54,$C$2) -> 710000 | E16: =D16/$E$2 -> 710000 | G16: =IF(F16="","",F16-E16) | H16: =IF(F16="","",IFERROR(F16/E16,0)) | I16: =IF(F16="","–",IF(H16>=1,"✅",IF(H16>=0.9,"⚠️","🚨"))) -> –
C17: CVR (%) | D17: 0.05 | E17: =D17 -> 0.05 | G17: =IF(F17="","",F17-E17) | H17: =IF(F17="","",IFERROR(F17/E17,0)) | I17: =IF(F17="","–",IF(H17>=1,"✅",IF(H17>=0.9,"⚠️","🚨"))) -> –
C18: AOV (IDR/order) | D18: 37700 | E18: =D18 -> 37700 | G18: =IF(F18="","",F18-E18) | H18: =IF(F18="","",IFERROR(F18/E18,0)) | I18: =IF(F18="","–",IF(H18>=1,"✅",IF(H18>=0.9,"⚠️","🚨"))) -> –
A20: L2 | B20: LAZADA | C20: GMV (IDR) | D20: =INDEX(Sheet1!$C$4:$C$15,$C$2) -> 39008113 | E20: =D20/$E$2 -> 39008113 | G20: =IF(F20="","",F20-E20) | H20: =IF(F20="","",IFERROR(F20/E20,0)) | I20: =IF(F20="","–",IF(H20>=1,"✅",IF(H20>=0.9,"⚠️","🚨"))) -> – | J20: =IF(OR(F21="",F22="",F23=""),"isi aktual dulu",IF(AND(H21<=H22,H21<=H23),"⬇ Traffic drag",IF(AND(H22<=H21,H22<=H23),"⬇ CVR drag","⬇ AOV drag"))) -> isi aktual dulu
C21: Traffic (Visitor) | D21: =INDEX(Sheet1!$D$62:$D$73,$C$2) -> 32000 | E21: =D21/$E$2 -> 32000 | G21: =IF(F21="","",F21-E21) | H21: =IF(F21="","",IFERROR(F21/E21,0)) | I21: =IF(F21="","–",IF(H21>=1,"✅",IF(H21>=0.9,"⚠️","🚨"))) -> –
C22: CVR (%) | D22: 0.02 | E22: =D22 -> 0.02 | G22: =IF(F22="","",F22-E22) | H22: =IF(F22="","",IFERROR(F22/E22,0)) | I22: =IF(F22="","–",IF(H22>=1,"✅",IF(H22>=0.9,"⚠️","🚨"))) -> –
C23: AOV (IDR/order) | D23: 71000 | E23: =D23 -> 71000 | G23: =IF(F23="","",F23-E23) | H23: =IF(F23="","",IFERROR(F23/E23,0)) | I23: =IF(F23="","–",IF(H23>=1,"✅",IF(H23>=0.9,"⚠️","🚨"))) -> –
A25: ▌ LAYER 3 — SUB-CHANNEL | Root Cause Spesifik
A26: Layer | B26: Channel | C26: Sub-Channel (% kontribusi) | D26: GMV Target Bulanan | E26: GMV Target Mingguan | F26: ✏ GMV AKTUAL | G26: Gap (IDR) | H26: Attainment | I26: Status | J26: Catatan
A27: L3 | B27: SHOPEE | C27: Live ID (25%) | D27: =INDEX(Sheet1!$C$24:$C$35,$C$2) -> 6.5338589e+08 | E27: =D27/$E$2 -> 6.5338589e+08 | G27: =IF(F27="","",F27-E27) | H27: =IF(F27="","",IFERROR(F27/E27,0)) | I27: =IF(F27="","–",IF(H27>=1,"✅",IF(H27>=0.9,"⚠️","🚨"))) -> –
A28: L3 | B28: SHOPEE | C28: Affiliate (15%) | D28: =INDEX(Sheet1!$D$24:$D$35,$C$2) -> 3.9203153e+08 | E28: =D28/$E$2 -> 3.9203153e+08 | G28: =IF(F28="","",F28-E28) | H28: =IF(F28="","",IFERROR(F28/E28,0)) | I28: =IF(F28="","–",IF(H28>=1,"✅",IF(H28>=0.9,"⚠️","🚨"))) -> –
A29: L3 | B29: SHOPEE | C29: Short Video (0.5%) | D29: =INDEX(Sheet1!$E$24:$E$35,$C$2) -> 13067718 | E29: =D29/$E$2 -> 13067718 | G29: =IF(F29="","",F29-E29) | H29: =IF(F29="","",IFERROR(F29/E29,0)) | I29: =IF(F29="","–",IF(H29>=1,"✅",IF(H29>=0.9,"⚠️","🚨"))) -> –
A31: L3 | B31: TIKTOKSHOP | C31: Livestream (20%) | D31: =INDEX(Sheet1!$C$43:$C$54,$C$2) -> 2.3014787e+08 | E31: =D31/$E$2 -> 2.3014787e+08 | G31: =IF(F31="","",F31-E31) | H31: =IF(F31="","",IFERROR(F31/E31,0)) | I31: =IF(F31="","–",IF(H31>=1,"✅",IF(H31>=0.9,"⚠️","🚨"))) -> –
A32: L3 | B32: TIKTOKSHOP | C32: Affiliate Video (80%) | D32: =INDEX(Sheet1!$D$43:$D$54,$C$2) -> 9.2059146e+08 | E32: =D32/$E$2 -> 9.2059146e+08 | G32: =IF(F32="","",F32-E32) | H32: =IF(F32="","",IFERROR(F32/E32,0)) | I32: =IF(F32="","–",IF(H32>=1,"✅",IF(H32>=0.9,"⚠️","🚨"))) -> –
A34: L3 | B34: LAZADA | C34: Lazada ID (semua) | D34: =INDEX(Sheet1!$B$62:$B$73,$C$2) -> 39008113 | E34: =D34/$E$2 -> 39008113 | G34: =IF(F34="","",F34-E34) | H34: =IF(F34="","",IFERROR(F34/E34,0)) | I34: =IF(F34="","–",IF(H34>=1,"✅",IF(H34>=0.9,"⚠️","🚨"))) -> –
A36: ▌ RINGKASAN DIAGNOSTIK OTOMATIS — Prioritas Tindakan Minggu Ini
A37: 🔴 Channel Terburuk | C37: =IF(AND(F10="",F15="",F20=""),"– isi aktual terlebih dahulu",IF(AND(H10<=H15,H10<=H20),"🚨 SHOPEE → "&TEXT(H10,"0.0%")&" attainment",IF(AND(H15<=H10,H15<=H20),"🚨 TIKTOKSHOP → "&TEXT(H15,"0.0%")&" attainment","🚨 LAZADA → "&TEXT(H20,"0.0%")&" attainment"))) -> – isi aktual terlebih dahulu
A38: 🟡 Lever Drag | C38: =IF(AND(F10="",F15="",F20=""),"– isi aktual terlebih dahulu","Lihat kolom J (⚡ Diagnosis) pada masing-masing channel di Layer 2 di atas") -> – isi aktual terlebih dahulu
A39: 🟢 Sub-Channel Kritis | C39: =IF(AND(F27="",F28="",F29="",F31="",F32=""),"– isi aktual terlebih dahulu",IF(AND(H27<=H28,H27<=H29,H27<=H31,H27<=H32),"🚨 Shopee Live → "&TEXT(H27,"0.0%"),IF(AND(H28<=H27,H28<=H29,H28<=H31,H28<=H32),"🚨 Shopee Affiliate → "&TEXT(H28,"0.0%"),IF(AND(H29<=H27,H29<=H28,H29<=H31,H29<=H32),"🚨 Shopee Video → "&TEXT(H29,"0.0%"),IF(AND(H31<=H27,H31<=H28,H31<=H29,H31<=H32),"🚨 TT Livestream → "&TEXT(H31,"0.0%"),"🚨 TT Affiliate → "&TEXT(H32,"0.0%")))))) -> – isi aktual terlebih dahulu
A41: ▌ PANDUAN
A42: ① Ubah C2 = bulan (1–12) ② Ubah E2 = minggu ke- (1–4) ③ Isi sel KUNING (aktual) ④ Baca Ringkasan baris 37-39 │ ✅ ≥100% ⚠️ 90-99% 🚨 <90% │ Kuning = input │ Hijau = target dari Sheet1

Sheet Monthly Diagnostic
A1: 📅 MONTHLY DIAGNOSTIC — Full-Year Monitoring 2026
A2: Bulan Aktif | B2: 6 | C2: ← Ubah B2 (1–12) untuk melihat detail channel & sub-channel bulan terpilih di bawah
A4: ▌ LAYER 1 — PERUSAHAAN | GMV Full-Year Tracker (Target vs Aktual)
A5: Bulan | B5: Q | C5: Target GMV (IDR) | D5: ✏ Aktual GMV (IDR) | E5: Gap (IDR) | F5: Attainment | G5: Status | H5: MoM Growth | I5: Catatan
A6: Januari | B6: Q1 | C6: =INDEX(Sheet1!$B$4:$B$15,1) -> 2.2636258e+09 | E6: =IF(D6="","",D6-C6) | F6: =IF(D6="","",IFERROR(D6/C6,0)) | G6: =IF(D6="","–",IF(F6>=1,"✅",IF(F6>=0.9,"⚠️","🚨"))) -> – | H6: –
A7: Februari | B7: Q1 | C7: =INDEX(Sheet1!$B$4:$B$15,2) -> 2.2636258e+09 | E7: =IF(D7="","",D7-C7) | F7: =IF(D7="","",IFERROR(D7/C7,0)) | G7: =IF(D7="","–",IF(F7>=1,"✅",IF(F7>=0.9,"⚠️","🚨"))) -> – | H7: =IF(OR(D7="",D6=""),"",IFERROR(D7/D6-1,""))
A8: Maret | B8: Q1 | C8: =INDEX(Sheet1!$B$4:$B$15,3) -> 2.2636258e+09 | E8: =IF(D8="","",D8-C8) | F8: =IF(D8="","",IFERROR(D8/C8,0)) | G8: =IF(D8="","–",IF(F8>=1,"✅",IF(F8>=0.9,"⚠️","🚨"))) -> – | H8: =IF(OR(D8="",D7=""),"",IFERROR(D8/D7-1,""))
A9: April | B9: Q2 | C9: =INDEX(Sheet1!$B$4:$B$15,4) -> 3.9008113e+09 | E9: =IF(D9="","",D9-C9) | F9: =IF(D9="","",IFERROR(D9/C9,0)) | G9: =IF(D9="","–",IF(F9>=1,"✅",IF(F9>=0.9,"⚠️","🚨"))) -> – | H9: =IF(OR(D9="",D8=""),"",IFERROR(D9/D8-1,""))
A10: Mei | B10: Q2 | C10: =INDEX(Sheet1!$B$4:$B$15,5) -> 3.9008113e+09 | E10: =IF(D10="","",D10-C10) | F10: =IF(D10="","",IFERROR(D10/C10,0)) | G10: =IF(D10="","–",IF(F10>=1,"✅",IF(F10>=0.9,"⚠️","🚨"))) -> – | H10: =IF(OR(D10="",D9=""),"",IFERROR(D10/D9-1,""))
A11: Juni | B11: Q2 | C11: =INDEX(Sheet1!$B$4:$B$15,6) -> 3.9008113e+09 | E11: =IF(D11="","",D11-C11) | F11: =IF(D11="","",IFERROR(D11/C11,0)) | G11: =IF(D11="","–",IF(F11>=1,"✅",IF(F11>=0.9,"⚠️","🚨"))) -> – | H11: =IF(OR(D11="",D10=""),"",IFERROR(D11/D10-1,""))
A12: Juli | B12: Q3 | C12: =INDEX(Sheet1!$B$4:$B$15,7) -> 3418126013 | E12: =IF(D12="","",D12-C12) | F12: =IF(D12="","",IFERROR(D12/C12,0)) | G12: =IF(D12="","–",IF(F12>=1,"✅",IF(F12>=0.9,"⚠️","🚨"))) -> – | H12: =IF(OR(D12="",D11=""),"",IFERROR(D12/D11-1,""))
A13: Agustus | B13: Q3 | C13: =INDEX(Sheet1!$B$4:$B$15,8) -> 3418126013 | E13: =IF(D13="","",D13-C13) | F13: =IF(D13="","",IFERROR(D13/C13,0)) | G13: =IF(D13="","–",IF(F13>=1,"✅",IF(F13>=0.9,"⚠️","🚨"))) -> – | H13: =IF(OR(D13="",D12=""),"",IFERROR(D13/D12-1,""))
A14: September | B14: Q3 | C14: =INDEX(Sheet1!$B$4:$B$15,9) -> 3418126013 | E14: =IF(D14="","",D14-C14) | F14: =IF(D14="","",IFERROR(D14/C14,0)) | G14: =IF(D14="","–",IF(F14>=1,"✅",IF(F14>=0.9,"⚠️","🚨"))) -> – | H14: =IF(OR(D14="",D13=""),"",IFERROR(D14/D13-1,""))
A15: Oktober | B15: Q4 | C15: =INDEX(Sheet1!$B$4:$B$15,10) -> 3750770213 | E15: =IF(D15="","",D15-C15) | F15: =IF(D15="","",IFERROR(D15/C15,0)) | G15: =IF(D15="","–",IF(F15>=1,"✅",IF(F15>=0.9,"⚠️","🚨"))) -> – | H15: =IF(OR(D15="",D14=""),"",IFERROR(D15/D14-1,""))
A16: November | B16: Q4 | C16: =INDEX(Sheet1!$B$4:$B$15,11) -> 3750770213 | E16: =IF(D16="","",D16-C16) | F16: =IF(D16="","",IFERROR(D16/C16,0)) | G16: =IF(D16="","–",IF(F16>=1,"✅",IF(F16>=0.9,"⚠️","🚨"))) -> – | H16: =IF(OR(D16="",D15=""),"",IFERROR(D16/D15-1,""))
A17: Desember | B17: Q4 | C17: =INDEX(Sheet1!$B$4:$B$15,12) -> 3750770213 | E17: =IF(D17="","",D17-C17) | F17: =IF(D17="","",IFERROR(D17/C17,0)) | G17: =IF(D17="","–",IF(F17>=1,"✅",IF(F17>=0.9,"⚠️","🚨"))) -> – | H17: =IF(OR(D17="",D16=""),"",IFERROR(D17/D16-1,""))
A19: Q1 | C19: =SUM(C6:C8) -> 6790877485 | D19: =SUM(D6:D8) -> 0 | E19: =IF(D19=0,"",D19-C19) | F19: =IF(D19=0,"",IFERROR(D19/C19,0)) | G19: =IF(D19=0,"–",IF(F19>=1,"✅",IF(F19>=0.9,"⚠️","🚨"))) -> – | I19: Partial jika belum semua bulan Q1 terisi
A20: Q2 | C20: =SUM(C9:C11) -> 11702433839 | D20: =SUM(D9:D11) -> 0 | E20: =IF(D20=0,"",D20-C20) | F20: =IF(D20=0,"",IFERROR(D20/C20,0)) | G20: =IF(D20=0,"–",IF(F20>=1,"✅",IF(F20>=0.9,"⚠️","🚨"))) -> – | I20: Partial jika belum semua bulan Q2 terisi
A21: Q3 | C21: =SUM(C12:C14) -> 10254378039 | D21: =SUM(D12:D14) -> 0 | E21: =IF(D21=0,"",D21-C21) | F21: =IF(D21=0,"",IFERROR(D21/C21,0)) | G21: =IF(D21=0,"–",IF(F21>=1,"✅",IF(F21>=0.9,"⚠️","🚨"))) -> – | I21: Partial jika belum semua bulan Q3 terisi
A22: Q4 | C22: =SUM(C15:C17) -> 11252310639 | D22: =SUM(D15:D17) -> 0 | E22: =IF(D22=0,"",D22-C22) | F22: =IF(D22=0,"",IFERROR(D22/C22,0)) | G22: =IF(D22=0,"–",IF(F22>=1,"✅",IF(F22>=0.9,"⚠️","🚨"))) -> – | I22: Partial jika belum semua bulan Q4 terisi
A23: YTD | C23: =SUM(C6:C17) -> 40000000002 | D23: =SUM(D6:D17) -> 0 | E23: =IF(D23=0,"",D23-C23) | F23: =IF(D23=0,"",IFERROR(D23/C23,0)) | G23: =IF(D23=0,"–",IF(F23>=1,"✅",IF(F23>=0.9,"⚠️","🚨"))) -> – | I23: Total target tahunan IDR 40 Miliar
A25: ▌ LAYER 2 — CHANNEL | Detail Bulan Terpilih — Traffic × CVR × AOV
A26: Layer | B26: Channel | C26: Metrik | D26: Target Bulanan | E26: ✏ Aktual | F26: Attainment | G26: Status | H26: Gap | I26: ⚡ Diagnosis Lever
A27: L2 | B27: SHOPEE | C27: GMV (IDR) | D27: =INDEX(Sheet1!$D$4:$D$15,$B$2) -> 2.6135436e+09 | F27: =IF(E27="","",IFERROR(E27/D27,0)) | G27: =IF(E27="","–",IF(F27>=1,"✅",IF(F27>=0.9,"⚠️","🚨"))) -> – | H27: =IF(E27="","",E27-D27) | I27: =IF(OR(E28="",E29="",E30=""),"isi aktual dulu",IF(AND(F28<=F29,F28<=F30),"⬇ Traffic drag",IF(AND(F29<=F28,F29<=F30),"⬇ CVR drag","⬇ AOV drag"))) -> isi aktual dulu
C28: Traffic (Visitor) | D28: =INDEX(Sheet1!$N$24:$N$35,$B$2) -> 399000 | F28: =IF(E28="","",IFERROR(E28/D28,0)) | G28: =IF(E28="","–",IF(F28>=1,"✅",IF(F28>=0.9,"⚠️","🚨"))) -> – | H28: =IF(E28="","",E28-D28)
C29: CVR (%) | D29: 0.072 | F29: =IF(E29="","",IFERROR(E29/D29,0)) | G29: =IF(E29="","–",IF(F29>=1,"✅",IF(F29>=0.9,"⚠️","🚨"))) -> – | H29: =IF(E29="","",E29-D29)
C30: AOV (IDR/order) | D30: 105000 | F30: =IF(E30="","",IFERROR(E30/D30,0)) | G30: =IF(E30="","–",IF(F30>=1,"✅",IF(F30>=0.9,"⚠️","🚨"))) -> – | H30: =IF(E30="","",E30-D30)
A32: L2 | B32: TIKTOKSHOP | C32: GMV (IDR) | D32: =INDEX(Sheet1!$F$4:$F$15,$B$2) -> 1.1507393e+09 | F32: =IF(E32="","",IFERROR(E32/D32,0)) | G32: =IF(E32="","–",IF(F32>=1,"✅",IF(F32>=0.9,"⚠️","🚨"))) -> – | H32: =IF(E32="","",E32-D32) | I32: =IF(OR(E33="",E34="",E35=""),"isi aktual dulu",IF(AND(F33<=F34,F33<=F35),"⬇ Traffic drag",IF(AND(F34<=F33,F34<=F35),"⬇ CVR drag","⬇ AOV drag"))) -> isi aktual dulu
C33: Traffic (Visitor) | D33: =INDEX(Sheet1!$G$43:$G$54,$B$2) -> 710000 | F33: =IF(E33="","",IFERROR(E33/D33,0)) | G33: =IF(E33="","–",IF(F33>=1,"✅",IF(F33>=0.9,"⚠️","🚨"))) -> – | H33: =IF(E33="","",E33-D33)
C34: CVR (%) | D34: 0.05 | F34: =IF(E34="","",IFERROR(E34/D34,0)) | G34: =IF(E34="","–",IF(F34>=1,"✅",IF(F34>=0.9,"⚠️","🚨"))) -> – | H34: =IF(E34="","",E34-D34)
C35: AOV (IDR/order) | D35: 37700 | F35: =IF(E35="","",IFERROR(E35/D35,0)) | G35: =IF(E35="","–",IF(F35>=1,"✅",IF(F35>=0.9,"⚠️","🚨"))) -> – | H35: =IF(E35="","",E35-D35)
A37: L2 | B37: LAZADA | C37: GMV (IDR) | D37: =INDEX(Sheet1!$C$4:$C$15,$B$2) -> 39008113 | F37: =IF(E37="","",IFERROR(E37/D37,0)) | G37: =IF(E37="","–",IF(F37>=1,"✅",IF(F37>=0.9,"⚠️","🚨"))) -> – | H37: =IF(E37="","",E37-D37) | I37: =IF(OR(E38="",E39="",E40=""),"isi aktual dulu",IF(AND(F38<=F39,F38<=F40),"⬇ Traffic drag",IF(AND(F39<=F38,F39<=F40),"⬇ CVR drag","⬇ AOV drag"))) -> isi aktual dulu
C38: Traffic (Visitor) | D38: =INDEX(Sheet1!$D$62:$D$73,$B$2) -> 32000 | F38: =IF(E38="","",IFERROR(E38/D38,0)) | G38: =IF(E38="","–",IF(F38>=1,"✅",IF(F38>=0.9,"⚠️","🚨"))) -> – | H38: =IF(E38="","",E38-D38)
C39: CVR (%) | D39: 0.02 | F39: =IF(E39="","",IFERROR(E39/D39,0)) | G39: =IF(E39="","–",IF(F39>=1,"✅",IF(F39>=0.9,"⚠️","🚨"))) -> – | H39: =IF(E39="","",E39-D39)
C40: AOV (IDR/order) | D40: 71000 | F40: =IF(E40="","",IFERROR(E40/D40,0)) | G40: =IF(E40="","–",IF(F40>=1,"✅",IF(F40>=0.9,"⚠️","🚨"))) -> – | H40: =IF(E40="","",E40-D40)
A42: ▌ LAYER 3 — SUB-CHANNEL | Detail Bulan Terpilih
A43: Layer | B43: Channel | C43: Sub-Channel | D43: GMV Target Bulanan | E43: ✏ GMV Aktual | F43: Attainment | G43: Status | H43: Gap (IDR) | I43: Catatan
A44: L3 | B44: SHOPEE | C44: Live ID (25%) | D44: =INDEX(Sheet1!$C$24:$C$35,$B$2) -> 6.5338589e+08 | F44: =IF(E44="","",IFERROR(E44/D44,0)) | G44: =IF(E44="","–",IF(F44>=1,"✅",IF(F44>=0.9,"⚠️","🚨"))) -> – | H44: =IF(E44="","",E44-D44)
A45: L3 | B45: SHOPEE | C45: Affiliate (15%) | D45: =INDEX(Sheet1!$D$24:$D$35,$B$2) -> 3.9203153e+08 | F45: =IF(E45="","",IFERROR(E45/D45,0)) | G45: =IF(E45="","–",IF(F45>=1,"✅",IF(F45>=0.9,"⚠️","🚨"))) -> – | H45: =IF(E45="","",E45-D45)
A46: L3 | B46: SHOPEE | C46: Short Video (0.5%) | D46: =INDEX(Sheet1!$E$24:$E$35,$B$2) -> 13067718 | F46: =IF(E46="","",IFERROR(E46/D46,0)) | G46: =IF(E46="","–",IF(F46>=1,"✅",IF(F46>=0.9,"⚠️","🚨"))) -> – | H46: =IF(E46="","",E46-D46)
...

Sheet Sheet1
A1: Doa 2026 (Stretch) | J1: Timeframe | K1: Doa
A2: Bulan | B2: Doa | C2: Lazada | D2: Shopee | E2: Qpreneur | F2: Tiktokshop | J2: Q1 | K2: =SUM(B4:B6) -> 6790877485
C3: 0.01 | D3: 0.67 | E3: 0.035 | F3: 0.295 | G3: =SUM(C3:F3) -> 1.01 | J3: Q2 | K3: =SUM(B7:B9) -> 11702433839
A4: Januari | B4: =6790877485/3 -> 2.2636258e+09 | C4: =B4*$C$3 -> 22636258 | D4: =B4*$D$3 -> 1.5166293e+09 | E4: =B4*$E$3 -> 79226904 | F4: =B4*$F$3 -> 6.6776962e+08 | G4: 0.1049916 | H4: =SUM(G4:G6) -> 0.35727567 | J4: Q3 | K4: =SUM(B10:B12) -> 10254378039
A5: Februari | B5: =6790877485/3 -> 2.2636258e+09 | C5: =B5*$C$3 -> 22636258 | D5: =B5*$D$3 -> 1.5166293e+09 | E5: =B5*$E$3 -> 79226904 | F5: =B5*$F$3 -> 6.6776962e+08 | G5: 0.11865997 | J5: Q4 | K5: =SUM(B13:B15) -> 11252310639
A6: Maret | B6: =6790877485/3 -> 2.2636258e+09 | C6: =B6*$C$3 -> 22636258 | D6: =B6*$D$3 -> 1.5166293e+09 | E6: =B6*$E$3 -> 79226904 | F6: =B6*$F$3 -> 6.6776962e+08 | G6: 0.13362409 | O6: 400000000
A7: April | B7: =(10391393000/3)+437013613 -> 3.9008113e+09 | C7: =B7*$C$3 -> 39008113 | D7: =B7*$D$3 -> 2.6135436e+09 | E7: =B7*$E$3 -> 1.3652839e+08 | F7: =B7*$F$3 -> 1.1507393e+09 | G7: 0.08 | H7: =SUM(G7:G9) -> 0.25716 | J7: Timeframe | K7: Lazada | L7: Shopee | M7: Qpreneur | N7: Tiktokshop | O7: Gift & Souvenir
A8: Mei | B8: =(10391393000/3)+437013613 -> 3.9008113e+09 | C8: =B8*$C$3 -> 39008113 | D8: =B8*$D$3 -> 2.6135436e+09 | E8: =B8*$E$3 -> 1.3652839e+08 | F8: =B8*$F$3 -> 1.1507393e+09 | G8: 0.087160002 | I8: =SUM(K8:N8)/$B$16 -> 0.17146966 | J8: Q1 | K8: =SUM(C4:C6) -> 67908775 | L8: =SUM(D4:D6) -> 4.5498879e+09 | M8: =SUM(E4:E6) -> 2.3768071e+08 | N8: =SUM(F4:F6) -> 2.0033089e+09 | O8: =$O$6*I8 -> 68587863
A9: Juni | B9: =(10391393000/3)+437013613 -> 3.9008113e+09 | C9: =B9*$C$3 -> 39008113 | D9: =B9*$D$3 -> 2.6135436e+09 | E9: =B9*$E$3 -> 1.3652839e+08 | F9: =B9*$F$3 -> 1.1507393e+09 | G9: 0.09 | I9: =SUM(K9:N9)/$B$16 -> 0.29548645 | J9: Q2 | K9: =SUM(C7:C9) -> 1.1702434e+08 | L9: =SUM(D7:D9) -> 7.8406307e+09 | M9: =SUM(E7:E9) -> 4.0958518e+08 | N9: =SUM(F7:F9) -> 3.452218e+09 | O9: =$O$6*I9 -> 1.1819458e+08
A10: July | B10: =(8943337200/3)+437013613 -> 3418126013 | C10: =B10*$C$3 -> 34181260 | D10: =B10*$D$3 -> 2.2901444e+09 | E10: =B10*$E$3 -> 1.1963441e+08 | F10: =B10*$F$3 -> 1.0083472e+09 | G10: 0.06 | H10: =SUM(G10:G12) -> 0.18 | I10: =SUM(K10:N10)/$B$16 -> 0.25892305 | J10: Q3 | K10: =SUM(C10:C12) -> 1.0254378e+08 | L10: =SUM(D10:D12) -> 6.8704333e+09 | M10: =SUM(E10:E12) -> 3.5890323e+08 | N10: =SUM(F10:F12) -> 3.0250415e+09 | O10: =$O$6*I10 -> 1.0356922e+08
A11: August | B11: =(8943337200/3)+437013613 -> 3418126013 | C11: =B11*$C$3 -> 34181260 | D11: =B11*$D$3 -> 2.2901444e+09 | E11: =B11*$E$3 -> 1.1963441e+08 | F11: =B11*$F$3 -> 1.0083472e+09 | G11: 0.06 | I11: =SUM(K11:N11)/$B$16 -> 0.28412084 | J11: Q4 | K11: =SUM(C13:C15) -> 1.1252311e+08 | L11: =SUM(D13:D15) -> 7.5390481e+09 | M11: =SUM(E13:E15) -> 3.9383087e+08 | N11: =SUM(F13:F15) -> 3.3194316e+09 | O11: =$O$6*I11 -> 1.1364834e+08
A12: September | B12: =(8943337200/3)+437013613 -> 3418126013 | C12: =B12*$C$3 -> 34181260 | D12: =B12*$D$3 -> 2.2901444e+09 | E12: =B12*$E$3 -> 1.1963441e+08 | F12: =B12*$F$3 -> 1.0083472e+09 | G12: 0.06 | K12: =SUM(K8:K11) -> 4e+08 | L12: =SUM(L8:L11) -> 2.68e+10 | M12: =SUM(M8:M11) -> 1.4e+09 | N12: =SUM(N8:N11) -> 1.18e+10
A13: October | B13: =(9941269800/3)+437013613 -> 3750770213 | C13: =B13*$C$3 -> 37507702 | D13: =B13*$D$3 -> 2.513016e+09 | E13: =B13*$E$3 -> 1.3127696e+08 | F13: =B13*$F$3 -> 1.1064772e+09 | G13: 0.07 | H13: =SUM(G13:G15) -> 0.21
A14: November | B14: =(9941269800/3)+437013613 -> 3750770213 | C14: =B14*$C$3 -> 37507702 | D14: =B14*$D$3 -> 2.513016e+09 | E14: =B14*$E$3 -> 1.3127696e+08 | F14: =B14*$F$3 -> 1.1064772e+09 | G14: 0.07
A15: December | B15: =(9941269800/3)+437013613 -> 3750770213 | C15: =B15*$C$3 -> 37507702 | D15: =B15*$D$3 -> 2.513016e+09 | E15: =B15*$E$3 -> 1.3127696e+08 | F15: =B15*$F$3 -> 1.1064772e+09 | G15: 0.07
A16: TOTAL | B16: =SUM(B4:B15) -> 40000000002 | C16: =SUM(C4:C15) -> 4e+08 | D16: =SUM(D4:D15) -> 2.68e+10 | E16: =SUM(E4:E15) -> 1.4e+09 | F16: =SUM(F4:F15) -> 1.18e+10 | G16: =SUM(G4:G15) -> 1.0044357
A17: GMV per day | B17: 365 | C17: =C16/$B$17 -> 1095890.4 | D17: =D16/$B$17 -> 73424658 | E17: =E16/$B$17 -> 3835616.4 | F17: =F16/$B$17 -> 32328767
A18: GMV per week | B18: 52 | C18: =$B$18*C16 -> 2.08e+10 | D18: =$B$18*D16 -> 1.3936e+12 | E18: =$B$18*E16 -> 7.28e+10 | F18: =$B$18*F16 -> 6.136e+11
A21: SHOPEE
A22: Bulan | B22: Doa | C22: SHOPEE LIVE ID | D22: AFFILIATE (Khania) | E22: VIDEO | F22: SHOPEE MY | G22: VIDEO | H22: SHOPEE MY | I22: DIKELOLA SHOPEE | J22: SHOPEE LIVE MY | K22: SHOPEE AFFILIATE MY | L22: SHOPEE VIDEO MY | M22: CONVERSION | N22: TRAFFIC | O22: AVERAGE SALES
C23: 0.25 | D23: 0.15 | E23: 0.005 | F23: 0.03 | G23: 2.005 | H23: 0.02 | I23: 0.03 | J23: 0.25 | K23: 0.15 | L23: 0.005
A24: =A4 -> Januari | B24: =D4 -> 1.5166293e+09 | C24: =B24*$C$23 -> 3.7915733e+08 | D24: =B24*$D$23 -> 2.274944e+08 | E24: =B24*$E$23 -> 7583146.5 | F24: =B24*$F$23 -> 45498879 | G24: =D24*$E$23 -> 1137472 | H24: =B24*$H$23 -> 30332586 | I24: =B24*$I$23 -> 45498879 | J24: =F24*$J$23 -> 11374720 | K24: =F24*$K$23 -> 6824831.9 | L24: =F24*$L$23 -> 227494.4 | M24: 0.072 | N24: 465500 | O24: 105000 | P24: =(N24*M24)*O24 -> 3519180000 | Q24: =B24 -> 1.5166293e+09
A25: =A5 -> Februari | B25: =D5 -> 1.5166293e+09 | C25: =B25*$C$23 -> 3.7915733e+08 | D25: =B25*$D$23 -> 2.274944e+08 | E25: =B25*$E$23 -> 7583146.5 | F25: =B25*$F$23 -> 45498879 | G25: =D25*$E$23 -> 1137472 | H25: =B25*$H$23 -> 30332586 | I25: =B25*$I$23 -> 45498879 | J25: =F25*$J$23 -> 11374720 | K25: =F25*$K$23 -> 6824831.9 | L25: =F25*$L$23 -> 227494.4 | M25: 0.072 | N25: 525800 | O25: 105000 | P25: =(N25*M25)*O25 -> 3975048000 | Q25: =B25 -> 1.5166293e+09
A26: =A6 -> Maret | B26: =D6 -> 1.5166293e+09 | C26: =B26*$C$23 -> 3.7915733e+08 | D26: =B26*$D$23 -> 2.274944e+08 | E26: =B26*$E$23 -> 7583146.5 | F26: =B26*$F$23 -> 45498879 | G26: =D26*$E$23 -> 1137472 | H26: =B26*$H$23 -> 30332586 | I26: =B26*$I$23 -> 45498879 | J26: =F26*$J$23 -> 11374720 | K26: =F26*$K$23 -> 6824831.9 | L26: =F26*$L$23 -> 227494.4 | M26: 0.072 | N26: 592300 | O26: 105000 | P26: =(N26*M26)*O26 -> 4477788000 | Q26: =B26 -> 1.5166293e+09
A27: =A7 -> April | B27: =D7 -> 2.6135436e+09 | C27: =B27*$C$23 -> 6.5338589e+08 | D27: =B27*$D$23 -> 3.9203153e+08 | E27: =B27*$E$23 -> 13067718 | F27: =B27*$F$23 -> 78406307 | G27: =D27*$E$23 -> 1960157.7 | H27: =B27*$H$23 -> 52270871 | I27: =B27*$I$23 -> 78406307 | J27: =F27*$J$23 -> 19601577 | K27: =F27*$K$23 -> 11760946 | L27: =F27*$L$23 -> 392031.53 | M27: 0.072 | N27: 355000 | O27: 105000 | P27: =(N27*M27)*O27 -> 2683800000 | Q27: =B27 -> 2.6135436e+09
A28: =A8 -> Mei | B28: =D8 -> 2.6135436e+09 | C28: =B28*$C$23 -> 6.5338589e+08 | D28: =B28*$D$23 -> 3.9203153e+08 | E28: =B28*$E$23 -> 13067718 | F28: =B28*$F$23 -> 78406307 | G28: =D28*$E$23 -> 1960157.7 | H28: =B28*$H$23 -> 52270871 | I28: =B28*$I$23 -> 78406307 | J28: =F28*$J$23 -> 19601577 | K28: =F28*$K$23 -> 11760946 | L28: =F28*$L$23 -> 392031.53 | M28: 0.072 | N28: 386500 | O28: 105000 | P28: =(N28*M28)*O28 -> 2921940000 | Q28: =B28 -> 2.6135436e+09
A29: =A9 -> Juni | B29: =D9 -> 2.6135436e+09 | C29: =B29*$C$23 -> 6.5338589e+08 | D29: =B29*$D$23 -> 3.9203153e+08 | E29: =B29*$E$23 -> 13067718 | F29: =B29*$F$23 -> 78406307 | G29: =D29*$E$23 -> 1960157.7 | H29: =B29*$H$23 -> 52270871 | I29: =B29*$I$23 -> 78406307 | J29: =F29*$J$23 -> 19601577 | K29: =F29*$K$23 -> 11760946 | L29: =F29*$L$23 -> 392031.53 | M29: 0.072 | N29: 399000 | O29: 105000 | P29: =(N29*M29)*O29 -> 3016440000 | Q29: =B29 -> 2.6135436e+09
A30: =A10 -> July | B30: =D10 -> 2.2901444e+09 | C30: =B30*$C$23 -> 5.7253611e+08 | D30: =B30*$D$23 -> 3.4352166e+08 | E30: =B30*$E$23 -> 11450722 | F30: =B30*$F$23 -> 68704333 | G30: =D30*$E$23 -> 1717608.3 | H30: =B30*$H$23 -> 45802889 | I30: =B30*$I$23 -> 68704333 | J30: =F30*$J$23 -> 17176083 | K30: =F30*$K$23 -> 10305650 | L30: =F30*$L$23 -> 343521.66 | M30: 0.072 | N30: 266000 | O30: 105000 | P30: =(N30*M30)*O30 -> 2010960000 | Q30: =B30 -> 2.2901444e+09
A31: =A11 -> August | B31: =D11 -> 2.2901444e+09 | C31: =B31*$C$23 -> 5.7253611e+08 | D31: =B31*$D$23 -> 3.4352166e+08 | E31: =B31*$E$23 -> 11450722 | F31: =B31*$F$23 -> 68704333 | G31: =D31*$E$23 -> 1717608.3 | H31: =B31*$H$23 -> 45802889 | I31: =B31*$I$23 -> 68704333 | J31: =F31*$J$23 -> 17176083 | K31: =F31*$K$23 -> 10305650 | L31: =F31*$L$23 -> 343521.66 | M31: 0.072 | N31: 266000 | O31: 105000 | P31: =(N31*M31)*O31 -> 2010960000 | Q31: =B31 -> 2.2901444e+09
A32: =A12 -> September | B32: =D12 -> 2.2901444e+09 | C32: =B32*$C$23 -> 5.7253611e+08 | D32: =B32*$D$23 -> 3.4352166e+08 | E32: =B32*$E$23 -> 11450722 | F32: =B32*$F$23 -> 68704333 | G32: =D32*$E$23 -> 1717608.3 | H32: =B32*$H$23 -> 45802889 | I32: =B32*$I$23 -> 68704333 | J32: =F32*$J$23 -> 17176083 | K32: =F32*$K$23 -> 10305650 | L32: =F32*$L$23 -> 343521.66 | M32: 0.072 | N32: 266000 | O32: 105000 | P32: =(N32*M32)*O32 -> 2010960000 | Q32: =B32 -> 2.2901444e+09
A33: =A13 -> October | B33: =D13 -> 2.513016e+09 | C33: =B33*$C$23 -> 6.2825401e+08 | D33: =B33*$D$23 -> 3.7695241e+08 | E33: =B33*$E$23 -> 12565080 | F33: =B33*$F$23 -> 75390481 | G33: =D33*$E$23 -> 1884762 | H33: =B33*$H$23 -> 50260321 | I33: =B33*$I$23 -> 75390481 | J33: =F33*$J$23 -> 18847620 | K33: =F33*$K$23 -> 11308572 | L33: =F33*$L$23 -> 376952.41 | M33: 0.072 | N33: 310500 | O33: 105000 | P33: =(N33*M33)*O33 -> 2347380000 | Q33: =B33 -> 2.513016e+09
A34: =A14 -> November | B34: =D14 -> 2.513016e+09 | C34: =B34*$C$23 -> 6.2825401e+08 | D34: =B34*$D$23 -> 3.7695241e+08 | E34: =B34*$E$23 -> 12565080 | F34: =B34*$F$23 -> 75390481 | G34: =D34*$E$23 -> 1884762 | H34: =B34*$H$23 -> 50260321 | I34: =B34*$I$23 -> 75390481 | J34: =F34*$J$23 -> 18847620 | K34: =F34*$K$23 -> 11308572 | L34: =F34*$L$23 -> 376952.41 | M34: 0.072 | N34: 310500 | O34: 105000 | P34: =(N34*M34)*O34 -> 2347380000 | Q34: =B34 -> 2.513016e+09
A35: =A15 -> December | B35: =D15 -> 2.513016e+09 | C35: =B35*$C$23 -> 6.2825401e+08 | D35: =B35*$D$23 -> 3.7695241e+08 | E35: =B35*$E$23 -> 12565080 | F35: =B35*$F$23 -> 75390481 | G35: =D35*$E$23 -> 1884762 | H35: =B35*$H$23 -> 50260321 | I35: =B35*$I$23 -> 75390481 | J35: =F35*$J$23 -> 18847620 | K35: =F35*$K$23 -> 11308572 | L35: =F35*$L$23 -> 376952.41 | M35: 0.072 | N35: 310500 | O35: 105000 | P35: =(N35*M35)*O35 -> 2347380000 | Q35: =B35 -> 2.513016e+09
A36: ='[1]doa stretch & konven'!i18 -> #NAME? | B36: =SUM(B24:B35) -> 2.68e+10 | C36: =SUM(C24:C35) -> 6.7e+09 | D36: =SUM(D24:D35) -> 4.02e+09 | E36: =SUM(E24:E35) -> 1.34e+08 | F36: =SUM(F24:F35) -> 8.04e+08 | G36: =SUM(G24:G35) -> 20100000 | H36: =SUM(H24:H35) -> 5.36e+08 | I36: =SUM(I24:I35) -> 8.04e+08 | ... L36: =SUM(L24:L35) -> 4020000 | M36: =AVERAGE(M24:M35) -> 0.072 | N36: =SUM(N24:N35) -> 4453600 | O36: =AVERAGE(O24:O35) -> 105000
A37: GMV per day | B37: 365 | C37: =C36/$B$37 -> 18356164 | D37: =D36/$B$37 -> 11013699 | E37: =E36/$B$37 -> 367123.29 | F37: =F36/$B$37 -> 2202739.7 | G37: =G36/$B$37 -> 55068.493 | H37: =H36/B37 -> 1468493.2 | I37: =I36/B37 -> 2202739.7
A40: TIKTOK
A41: Bulan | B41: Doa | C41: LIVESTREAM | D41: AFFILIATE | E41: OWN ACCOUNT | F41: CONVERSION | G41: TRAFFIC VIDEO | H41: TRAFFIC | I41: TRAFFIC | J41: AVERAGE SALES
C42: 0.2 | D42: 0.8 | E42: 0.07
A43: =A24 -> Januari | B43: =F4 -> 6.6776962e+08 | C43: =B43*$C$42 -> 1.3355392e+08 | D43: =B43*$D$42 -> 5.342157e+08 | E43: =B43*$E$42 -> 46743873 | F43: 0.05 | G43: 822000 | J43: 37700
A44: =A25 -> Februari | B44: =F5 -> 6.6776962e+08 | C44: =B44*$C$42 -> 1.3355392e+08 | D44: =B44*$D$42 -> 5.342157e+08 | E44: =B44*$E$42 -> 46743873 | F44: 0.05 | G44: 929000 | J44: 37700
...
